Workbook

Sheet Barcelona
A1: id | B1: name | C1: host_id | D1: host_profile_id | E1: host_name | F1: neighbourhood_group | G1: neighbourhood | H1: latitude | I1: longitude | J1: room_type | K1: price | L1: minimum_nights | M1: number_of_reviews | N1: last_review | O1: reviews_per_month | P1: calculated_host_listings_count | Q1: availability_365 | R1: number_of_reviews_ltm | S1: license
A2: 18674 | B2: Huge flat for 8 people close to Sagrada Familia | C2: 71615 | D2: 1.4625084e+18 | E2: Mireia | F2: Eixample | G2: la Sagrada FamÃ­lia | H2: 41.40556 | I2: 2.17262 | J2: Entire home/apt | L2: 1 | M2: 54 | N2: 45980 | O2: 0.35 | P2: 24 | Q2: 115 | R2: 9 | S2: Spain - National registration number<br />ESFCTU000008058000039706000000000000000HUTB-002062349<br /><br />Barcelona - Regional registration number<br />HUTB-002062
A3: 2031134 | B3: Sagrada Familia-auditorium. FREE WI-FI. | C3: 9100900 | D3: 1.4627949e+18 | E3: Miguel | F3: Eixample | G3: el Fort Pienc | H3: 41.40001 | I3: 2.18416 | J3: Entire home/apt | L3: 2 | M3: 453 | N3: 45993 | O3: 3.16 | P3: 1 | Q3: 294 | R3: 52 | S3: Barcelona - Regional registration number<br />HUTB-008524<br /><br />Spain - National registration number<br />ESFCTU00000807200012837600000000000000000HUTB-0085249
A4: 4415694 | B4: DEEP PURPLE - RAMBLES | C4: 12385333 | D4: 1.4628866e+18 | E4: Yolanda | F4: Sants-MontjuÃ¯c | G4: el Poble Sec | H4: 41.3723 | I4: 2.16441 | J4: Entire home/apt | L4: 3 | M4: 182 | N4: 45970 | O4: 1.39 | P4: 2 | Q4: 115 | R4: 11 | S4: Barcelona - Regional registration number<br />HUTB-006856
A5: 4415780 | B5: Double Room "Barcelona" | C5: 4990426 | D5: 1.4626702e+18 | E5: Judith | F5: GrÃ cia | G5: la Vila de GrÃ cia | H5: 41.40667 | I5: 2.16152 | J5: Private room | L5: 1 | M5: 5 | N5: 42662 | O5: 0.04 | P5: 1 | Q5: 0 | R5: 0
A6: 5064035 | B6: Lovely 2 BD with terrace and wifi | C6: 1744516 | D6: 1.4625773e+18 | E6: Silvia & LuÃ­s | F6: GrÃ cia | G6: la Vila de GrÃ cia | H6: 41.39996 | I6: 2.16339 | J6: Entire home/apt | L6: 3 | M6: 128 | N6: 45991 | O6: 0.99 | P6: 39 | Q6: 222 | R6: 23 | S6: Spain - National registration number<br />ESHFTU00000805700055108900800000000000000HUTB-0074460
A7: 5064651 | B7: Nice cute room for one person | C7: 26153633 | D7: 1.4653566e+18 | E7: Rabea | F7: Eixample | G7: la Sagrada FamÃ­lia | H7: 41.40687 | I7: 2.17813 | J7: Private room | L7: 1 | M7: 9 | N7: 43043 | O7: 0.07 | P7: 1 | Q7: 0 | R7: 0
A8: 6163177 | B8: Piso a 100 mts de la playa de BCN | C8: 31970000 | D8: 1.462657e+18 | E8: Pablo | F8: Sant MartÃ­ | G8: el Poblenou | H8: 41.39782 | I8: 2.20745 | J8: Private room | L8: 32 | M8: 14 | N8: 43324 | O8: 0.11 | P8: 1 | Q8: 365 | R8: 0
A9: 8414793 | B9: Lugaris Beach Premium Apartment | C9: 375625 | D9: 1.4625115e+18 | E9: Xavier | F9: Sant MartÃ­ | G9: el Poblenou | H9: 41.39909 | I9: 2.20733 | J9: Entire home/apt | L9: 1 | M9: 300 | N9: 45982 | O9: 2.47 | P9: 5 | Q9: 190 | R9: 96 | S9: Barcelona - Regional registration number<br />HUTB-002924
A10: 9357521 | B10: Three bedroom apartment Gran de Gracia You Stylish | C10: 8130906 | D10: 1.46275e+18 | E10: Eva | F10: GrÃ cia | G10: la Vila de GrÃ cia | H10: 41.39897 | I10: 2.15688 | J10: Entire home/apt | L10: 1 | M10: 160 | N10: 45972 | O10: 1.36 | P10: 64 | Q10: 325 | R10: 23 | S10: Barcelona - Regional registration number<br />HUTB-010949<br /><br />Spain - National registration number<br />ESFCTU00000806600038174900000000000000000HUTB-0109493
A11: 9358082 | B11: Bright, friendly and nice flat ! | C11: 48562201 | D11: 1.4657359e+18 | E11: Marie-GÃ©raldine | F11: Sant MartÃ­ | G11: el Clot | H11: 41.41029 | I11: 2.18694 | J11: Private room | L11: 1 | M11: 0 | P11: 1 | Q11: 0 | R11: 0
A12: 9362251 | B12: Plaza Espanya Apartime | C12: 4396136 | D12: 1.4626564e+18 | E12: Homesearch | F12: Sants-MontjuÃ¯c | G12: el Poble Sec | H12: 41.37333 | I12: 2.15451 | J12: Entire home/apt | L12: 3 | M12: 42 | N12: 45417 | O12: 0.36 | P12: 13 | Q12: 221 | R12: 0 | S12: Barcelona - Regional registration number<br />HUTB-005253
A13: 10031534 | B13: Cosy 1 BD APT with Balcony in Sagrada Familia | C13: 1744516 | D13: 1.4625773e+18 | E13: Silvia & LuÃ­s | F13: Eixample | G13: la Sagrada FamÃ­lia | H13: 41.40704 | I13: 2.18098 | J13: Entire home/apt | L13: 3 | M13: 58 | N13: 45972 | O13: 0.49 | P13: 39 | Q13: 296 | R13: 11 | S13: Spain - National registration number<br />ESFCTU000008073000928126000000000000000000HUTB0104059
A14: 10038461 | B14: Voyage Apart-Barcelona city centre | C14: 4687292 | D14: 1.4626633e+18 | E14: Gian | F14: Sants-MontjuÃ¯c | G14: el Poble Sec | H14: 41.37431 | I14: 2.16577 | J14: Entire home/apt | L14: 2 | M14: 464 | N14: 45984 | O14: 3.83 | P14: 1 | Q14: 251 | R14: 51 | S14: Spain - National registration number<br />ESFCTU00000806900001257600000000000000000HUTB-0027713<br /><br />Barcelona - Regional registration number<br />HUTB-002771
A15: 10078923 | B15: Barceloneta Street apartment | C15: 4116737 | D15: 1.4626478e+18 | E15: Elyess | F15: Ciutat Vella | G15: la Barceloneta | H15: 41.38223 | I15: 2.18798 | J15: Entire home/apt | L15: 31 | M15: 45 | N15: 45962 | O15: 0.38 | P15: 1 | Q15: 203 | R15: 5
A16: 11004309 | B16: Jardinets de GrÃ cia C, Barcelona! HUTB - 009099-92 | C16: 2688205 | D16: 1.4625257e+18 | E16: MÃ²nica | F16: GrÃ cia | G16: la Vila de GrÃ cia | H16: 41.39888 | I16: 2.16226 | J16: Entire home/apt | L16: 3 | M16: 396 | N16: 45992 | O16: 3.32 | P16: 13 | Q16: 226 | R16: 57 | S16: Barcelona - Regional registration number<br />HUTB-009099<br /><br />Spain - National registration number<br />ESFCTU00000805600026508800000000000000000HUTB-0126724
A17: 11008465 | B17: Sagrada Familia terrace flat | C17: 3744544 | D17: 1.4625316e+18 | E17: Marta+Paul | F17: Eixample | G17: la Sagrada FamÃ­lia | H17: 41.4055 | I17: 2.17727 | J17: Entire home/apt | L17: 3 | M17: 220 | N17: 45989 | O17: 1.9 | P17: 33 | Q17: 257 | R17: 35 | S17: Barcelona - Regional registration number<br />hutb-008493<br /><br />Spain - National registration number<br />ESFCTU00000807300025677900000000000000HUTB-008493-766
A18: 11547762 | B18: Big and central beautiful room | C18: 60951178 | D18: 1.4667505e+18 | E18: Yohanna | F18: Ciutat Vella | G18: la Barceloneta | H18: 41.38153 | I18: 2.18519 | J18: Private room | L18: 1 | M18: 2 | N18: 42529 | O18: 0.02 | P18: 1 | Q18: 0 | R18: 0
A19: 11550809 | B19: Excelente ubicaciÃ³n & fast Wifi | C19: 42613804 | D19: 1.4626911e+18 | E19: Vanina | F19: Eixample | G19: Sant Antoni | H19: 41.37554 | I19: 2.1649 | J19: Entire home/apt | L19: 32 | M19: 42 | N19: 45991 | O19: 0.36 | P19: 2 | Q19: 316 | R19: 2
A20: 11566581 | B20: Awesome double room in gotico area | C20: 12647360 | D20: 1.4628925e+18 | E20: Adam | F20: Ciutat Vella | G20: el Barri GÃ²tic | H20: 41.38183 | I20: 2.17637 | J20: Private room | L20: 3 | M20: 6 | N20: 42708 | O20: 0.05 | P20: 1 | Q20: 0 | R20: 0
A21: 11568230 | B21: B-Apartamento en casco antiguo. | C21: 22076771 | D21: 1.463171e+18 | E21: Luis | F21: Ciutat Vella | G21: el Barri GÃ²tic | H21: 41.38039 | I21: 2.17708 | J21: Entire home/apt | L21: 30 | M21: 15 | N21: 45897 | O21: 0.13 | P21: 20 | Q21: 246 | R21: 4 | S21: Spain - National registration number<br />ESFCNT00000811900021351700000000000000000000000000007
A22: 12355911 | B22: Room next to metro w/ own bathroom | C22: 143513 | D22: 1.46251e+18 | E22: Nabeelah | F22: Horta-GuinardÃ³ | G22: la Teixonera | H22: 41.42369 | I22: 2.14722 | J22: Private room | L22: 2 | M22: 40 | N22: 42910 | O22: 0.34 | P22: 1 | Q22: 0 | R22: 0
A23: 13093469 | B23: COZY DOUBLE ROOM IN PLAZA DE ESPAÃ‘A | C23: 16254397 | D23: 1.4629823e+18 | E23: Silvia | F23: Eixample | G23: Sant Antoni | H23: 41.37654 | I23: 2.1519 | J23: Private room | L23: 1 | M23: 0 | P23: 1 | Q23: 0 | R23: 0
A24: 13103577 | B24: Sunny Gothik and Port Apartment | C24: 2262273 | D24: 1.4625904e+18 | E24: Maria Rosa | F24: Ciutat Vella | G24: el Barri GÃ²tic | H24: 41.38149 | I24: 2.18035 | J24: Entire home/apt | L24: 32 | M24: 6 | N24: 44843 | O24: 0.07 | P24: 31 | Q24: 166 | R24: 0
A25: 13106697 | B25: La MediterrÃ¡nea - Homecelona Apts | C25: 2748428 | D25: 1.4625261e+18 | E25: Sha | F25: Sant MartÃ­ | G25: el Poblenou | H25: 41.395979 | I25: 2.2063944 | J25: Entire home/apt | L25: 4 | M25: 356 | N25: 45984 | O25: 3.08 | P25: 7 | Q25: 249 | R25: 39 | S25: Barcelona - Regional registration number<br />HUTB-009201<br /><br />Spain - National registration number<br />ESFCTU00000807200058235200000000000000HUTB-009201-366
A26: 13552869 | B26: Charming Private Room in City Centre. | C26: 16170032 | D26: 1.4629803e+18 | E26: Roberto | F26: Eixample | G26: Sant Antoni | H26: 41.37976 | I26: 2.1602 | J26: Private room | L26: 20 | M26: 3 | N26: 42595 | O26: 0.03 | P26: 1 | Q26: 0 | R26: 0
A27: 13844132 | B27: Nice Room in the Center of the city | C27: 81711867 | D27: 1.4669929e+18 | E27: Uxue | F27: Ciutat Vella | G27: el Raval | H27: 41.37752 | I27: 2.17272 | J27: Private room | L27: 3 | M27: 14 | N27: 42647 | O27: 0.12 | P27: 1 | Q27: 0 | R27: 0
A28: 14371490 | B28: Great Views, Near Beach, Port Vell | C28: 75620994 | D28: 1.4628158e+18 | E28: Sabrina | F28: Ciutat Vella | G28: el Barri GÃ²tic | H28: 41.38179 | I28: 2.18048 | J28: Entire home/apt | L28: 31 | M28: 14 | N28: 45869 | O28: 0.13 | P28: 13 | Q28: 365 | R28: 1 | S28: Spain - National registration number<br />ESFCNT00000811900011659700000000000000000000000000007
A29: 14378795 | B29: Downtown Barcelona! Ramblas, Plaza CataluÃ±a! | C29: 56503135 | D29: 1.4627347e+18 | E29: Flor | F29: Ciutat Vella | G29: el Barri GÃ²tic | H29: 41.38127 | I29: 2.17378 | J29: Private room | L29: 2 | M29: 325 | N29: 45613 | O29: 2.86 | P29: 2 | Q29: 0 | R29: 0
A30: 15293599 | B30: Big cozy aptm w/Central Heating by Las Ramblas! | C30: 55103645 | D30: 1.4659034e+18 | E30: David | F30: Ciutat Vella | G30: el Barri GÃ²tic | H30: 41.37959 | I30: 2.17627 | J30: Entire home/apt | L30: 32 | M30: 32 | N30: 45977 | O30: 0.29 | P30: 1 | Q30: 174 | R30: 7
A31: 15306390 | B31: Cozy Room at the City Center per long term rent | C31: 77548260 | D31: 1.4669505e+18 | E31: Andrea | F31: Eixample | G31: el Fort Pienc | H31: 41.39715 | I31: 2.17717 | J31: Private room | L31: 35 | M31: 16 | N31: 45809 | O31: 0.15 | P31: 8 | Q31: 105 | R31: 1 | S31: Spain - National registration number<br />ESHFNT00000805400056980900600000000000000000000000006
A32: 16266993 | B32: Acogedora habitaciÃ³n cerca de Sagrada Familia! | C32: 36607755 | D32: 1.4655452e+18 | E32: Room Housing | F32: Eixample | G32: la Sagrada FamÃ­lia | H32: 41.40302 | I32: 2.18124 | J32: Private room | L32: 32 | M32: 0 | P32: 136 | Q32: 365 | R32: 0
A33: 16270398 | B33: Nice dble bedroom to share next to the sea/center | C33: 106401998 | D33: 1.4672903e+18 | E33: Garnier | F33: Sant MartÃ­ | G33: el Poblenou | H33: 41.39752 | I33: 2.20144 | J33: Private room | L33: 3 | M33: 0 | P33: 1 | Q33: 0 | R33: 0
A34: 16278781 | B34: Kick Back on the Terrace of a Classic Home | C34: 8320838 | D34: 1.4627655e+18 | E34: Andrea And Jesse | F34: GrÃ cia | G34: la Vila de GrÃ cia | H34: 41.39759 | I34: 2.15418 | J34: Entire home/apt | L34: 2 | M34: 340 | N34: 45956 | O34: 3.12 | P34: 1 | Q34: 278 | R34: 30 | S34: Spain - National registration number<br />ESFCTU00000806600024844800000000000000000HUTB-0092304
A35: 16279645 | B35: Study in the center, in Gracia | C35: 94858265 | D35: 1.4671438e+18 | E35: Jose O | F35: GrÃ cia | G35: la Vila de GrÃ cia | H35: 41.39997 | I35: 2.1615 | J35: Entire home/apt | L35: 5 | M35: 245 | N35: 45971 | O35: 2.24 | P35: 4 | Q35: 140 | R35: 33 | S35: Spain - National registration number<br />ESFCTU000008057000241461000000000000000000HUTB0062672<br /><br />Barcelona - Regional registration number<br />HUTB-006267
A36: 16292600 | B36: BCN Luxury | C36: 15944590 | D36: 1.4629744e+18 | E36: Paco | F36: Eixample | G36: Sant Antoni | H36: 41.38521 | I36: 2.16299 | J36: Entire home/apt | L36: 4 | M36: 234 | N36: 45989 | O36: 2.15 | P36: 2 | Q36: 336 | R36: 31 | S36: Barcelona - Regional registration number<br />HUTB-013202
A37: 16294662 | B37: Double room in Villa de Gracia | C37: 106602227 | D37: 1.4672926e+18 | E37: Celia | F37: GrÃ cia | G37: la Vila de GrÃ cia | H37: 41.40071 | I37: 2.15473 | J37: Private room | L37: 1 | M37: 15 | N37: 43387 | O37: 0.14 | P37: 1 | Q37: 0 | R37: 0
A38: 16306389 | B38: Relaxing room in Sagrada Familia! | C38: 36607755 | D38: 1.4655452e+18 | E38: Room Housing | F38: Eixample | G38: la Sagrada FamÃ­lia | H38: 41.40496 | I38: 2.18148 | J38: Private room | L38: 32 | M38: 0 | P38: 136 | Q38: 364 | R38: 0
A39: 16306731 | B39: Beautiful & shinny room near to Sagrada Familia! | C39: 36607755 | D39: 1.4655452e+18 | E39: Room Housing | F39: Eixample | G39: la Sagrada FamÃ­lia | H39: 41.40458 | I39: 2.18123 | J39: Private room | L39: 32 | M39: 0 | P39: 136 | Q39: 364 | R39: 0
A40: 16306813 | B40: HabitaciÃ³n Soleada en Sagrada Familia! | C40: 36607755 | D40: 1.4655452e+18 | E40: Room Housing | F40: Eixample | G40: la Sagrada FamÃ­lia | H40: 41.4039 | I40: 2.17934 | J40: Private room | L40: 32 | M40: 0 | P40: 136 | Q40: 364 | R40: 0
...

Sheet Stats
A1: Statistic | B1: Minimum Nights | C1: Number of reviews | D1: Availability 365 | E1: Calculated Host Listings Count
A2: Mean | B2: =AVERAGE(Barcelona!L:L) -> 16.592507 | C2: =AVERAGE(Barcelona!R:R) -> 11.200638 | D2: =AVERAGE(Barcelona!Q:Q) -> 209.57215 | E2: =AVERAGE(Barcelona!P:P) -> 68.490235
A3: Median | B3: =MEDIAN(Barcelona!L:L) -> 3 | C3: =MEDIAN(Barcelona!R:R) -> 1 | D3: =MEDIAN(Barcelona!Q:Q) -> 245 | E3: =MEDIAN(Barcelona!P:P) -> 9
A4: Mode | B4: =MODE(Barcelona!L:L) -> 1 | C4: =MODE(Barcelona!R:R) -> 0 | D4: =MODE(Barcelona!Q:Q) -> 0 | E4: =MODE(Barcelona!P:P) -> 1
A5: Std Deviation | B5: =STDEV(Barcelona!L:L) -> 31.589899 | C5: =STDEV(Barcelona!R:R) -> 24.999374 | D5: =STDEV(Barcelona!Q:Q) -> 130.3137 | E5: =STDEV(Barcelona!P:P) -> 129.19512
A6: Variance | B6: =VAR(Barcelona!L:L) -> 997.92169 | C6: =VAR(Barcelona!R:R) -> 624.96871 | D6: =VAR(Barcelona!Q:Q) -> 16981.659 | E6: =VAR(Barcelona!P:P) -> 16691.379
A7: Min | B7: =MIN(Barcelona!L:L) -> 1 | C7: =MIN(Barcelona!R:R) -> 0 | D7: =MIN(Barcelona!Q:Q) -> 0 | E7: =MIN(Barcelona!P:P) -> 1
A8: Max | B8: =MAX(Barcelona!L:L) -> 1124 | C8: =MAX(Barcelona!R:R) -> 938 | D8: =MAX(Barcelona!Q:Q) -> 365 | E8: =MAX(Barcelona!P:P) -> 549
A9: Range | B9: =MAX(Barcelona!L:L)-MIN(Barcelona!L:L) -> 1123 | C9: =MAX(Barcelona!R:R)-MIN(Barcelona!R:R) -> 938 | D9: =MAX(Barcelona!Q:Q)-MIN(Barcelona!Q:Q) -> 365 | E9: =MAX(Barcelona!P:P)-MIN(Barcelona!P:P) -> 548
A10: Skewness | B10: =SKEW(Barcelona!L:L) -> 14.326116 | C10: =SKEW(Barcelona!R:R) -> 10.901382 | D10: =SKEW(Barcelona!Q:Q) -> -0.43426622 | E10: =SKEW(Barcelona!P:P) -> 2.3615706
A11: Kurtosis | B11: =KURT(Barcelona!L:L) -> 339.21108 | C11: =KURT(Barcelona!R:R) -> 277.00696 | D11: =KURT(Barcelona!Q:Q) -> -1.2864864 | E11: =KURT(Barcelona!P:P) -> 4.8759493
